Workbook

Sheet COMPARISON RESULTs
B2: COMPARISON
B4: No | D4: LiDAR_1 | E4: LiDAR_2 | F4: UAV_2 | G4: UAV_4
B5: 1 | C5: Measurement | D5: Wind speed: ±0.4 m/s | E5: Wind speed: ±0.4 m/s | F5: Wind speed: ±0.5 m/s | G5: Wind speed: ±0.5 m/s
D6: Wind direction: ±7°. | E6: Wind direction: ±7°. | F6: Wind direction: ±10°. | G6: Wind direction: ±10°.
D7: applied to measured data | E7: applied to measured data | F7: applied all turbines | G7: applied all turbines
B8: 2 | C8: Flow model/ Spacial variability | D8: Wind speed: ±8% | E8: Wind speed: ±5% | F8: Wind speed: ±5% | G8: 0
D9: (extrapolation) | E9: (intrapolation) | F9: (intrapolation)
D10: applied to all turbines | E10: applied to all turbines | F10: applied T4-6-12-14-18-19-20
B11: ENERGY YIELD
C12: Mean AEP (P50) [MWh] | D12: =C44 -> 468892.97 | E12: =C45 -> 470760.89 | F12: =C46 -> 471390.14 | G12: =C47 -> 472423.11
C13: ΔP50 [MWh] | D13: =D12-$D$12 -> 0 | E13: =E12-$D$12 -> 1867.9294 | F13: =F12-$D$12 -> 2497.1782 | G13: =G12-$D$12 -> 3530.1432
C14: ΔP50 [%] | D14: =(D12-$D$12)/$D$12 -> 0 | E14: =(E12-$D$12)/$D$12 -> 0.003983701 | F14: =(F12-$D$12)/$D$12 -> 0.0053256892 | G14: =(G12-$D$12)/$D$12 -> 0.007528676
C15: StdDev of P50 [MWh] | D15: =E44 -> 8916.1348 | E15: =E45 -> 5515.1486 | F15: =E46 -> 2385.3672 | G15: =E47 -> 92.086515
C16: StdDev of P50 [%] | D16: =D15/D12 -> 0.019015288 | E16: =E15/E12 -> 0.011715392 | F16: =F15/F12 -> 0.0050602822 | G16: =G15/G12 -> 0.00019492382
C17: P90 [MWh] | D17: =D44 -> 457106.36 | E17: =D45 -> 463535.8 | F17: =D46 -> 468140.86 | G17: =D47 -> 472303.49
C18: ΔP90 [MWh] | D18: =D17-$D$17 -> 0 | E18: =E17-$D$17 -> 6429.4416 | F18: =F17-$D$17 -> 11034.505 | G18: =G17-$D$17 -> 15197.134
C19: ΔP90 [%] | D19: =D17-$D$17 -> 0 | E19: =(E17-$D$17)/$D$17 -> 0.014065527 | F19: =(F17-$D$17)/$D$17 -> 0.024139907 | G19: =(G17-$D$17)/$D$17 -> 0.033246384
C20: ΔP90 [MWh] | D20: =D17-$D$17 -> 0 | E20: =E17-$D$17 -> 6429.4416 | F20: =F17-$D$17 -> 11034.505 | G20: =G17-$D$17 -> 15197.134
C21: P90 (Base case) [MWh] | D21: =D17-D20 -> 457106.36 | E21: =E17-E20 -> 457106.36 | F21: =F17-F20 -> 457106.36 | G21: =G17-G20 -> 457106.36
C22: P90/P50 ratio [%] | D22: =D17/D12 -> 0.9748629 | E22: =E17/E12 -> 0.9846523 | F22: =F17/F12 -> 0.99310702 | G22: =G17/G12 -> 0.9997468
B23: COST OF WRA CAMPAIGN (1 year)
C24: Cost [€] | D24: ='Renting LiDAR - UAVs'!H11 -> 75589.5 | E24: ='Renting LiDAR - UAVs'!Q11 -> 148180 | F24: ='Renting LiDAR - UAVs'!H29 -> 126832.5 | G24: ='Renting LiDAR - UAVs'!Q29 -> 205332.5
C25: ΔCost [€] | D25: ='COMPARISON RESULTs'!D24-'COMPARISON RESULTs'!$D$24 -> 0 | E25: ='COMPARISON RESULTs'!E24-'COMPARISON RESULTs'!$D$24 -> 72590.5 | F25: ='COMPARISON RESULTs'!F24-'COMPARISON RESULTs'!$D$24 -> 51243 | G25: ='COMPARISON RESULTs'!G24-'COMPARISON RESULTs'!$D$24 -> 129743
C26: ΔCost [%] | D26: =D25/$D$24 -> 0 | E26: =E25/$D$24 -> 0.96032518 | F26: =F25/$D$24 -> 0.67791161 | G26: =G25/$D$24 -> 1.7164156
B27: DSCR (Debt Service Coverage Ratio) Target (*) = 1.35. Project lifetime: 25 years
C28: Share of Debt [% CAPEX] | D28: ='Project finance'!J20 -> 0.88506568 | E28: ='Project finance'!K20 -> 0.89960621 | F28: ='Project finance'!L20 -> 0.91002081 | G28: ='Project finance'!M20 -> 0.91943482
C29: Δ Share of Debt [%] | D29: =D28-$D$28 -> 0 | E29: =E28-$D$28 -> 0.014540528 | F29: =F28-$D$28 -> 0.024955126 | G29: =G28-$D$28 -> 0.034369134
C30: WACC [%] | D30: ='Project finance'!J22 -> 0.046988292 | E30: ='Project finance'!K22 -> 0.046583773 | F30: ='Project finance'!L22 -> 0.046320777 | G30: ='Project finance'!M22 -> 0.046047393
C31: Δ WACC [%] | D31: ='Project finance'!J22-'Project finance'!$J$22 -> 0 | E31: ='Project finance'!K22-'Project finance'!$J$22 -> -0.00040451901 | F31: ='Project finance'!L22-'Project finance'!$J$22 -> -0.00066751562 | G31: ='Project finance'!M22-'Project finance'!$J$22 -> -0.00094089962
C32: NPV [€] | D32: ='Project finance'!J23 -> 73655594 | E32: ='Project finance'!K23 -> 79208524 | F32: ='Project finance'!L23 -> 83063816 | G32: ='Project finance'!M23 -> 86765322
C33: Δ NPV [€] | D33: =D32-$D$32 -> 0 | E33: =E32-$D$32 -> 5552929.9 | F33: =F32-$D$32 -> 9408221.3 | G33: =G32-$D$32 -> 13109727
C34: NPV (Base case) [€] | D34: =D32 -> 73655594 | E34: =E32-E33 -> 73655594 | F34: =F32-F33 -> 73655594 | G34: =G32-G33 -> 73655594
C35: Δ NPV [%] | D35: =D33/$D$32 -> 0 | E35: =E33/$D$32 -> 0.07539047 | F35: =F33/$D$32 -> 0.12773261 | G35: =G33/$D$32 -> 0.17798685
B36: Return on investment (ΔNPV per extra € of WRA spend)
C37: ΔNPV/ΔCost (€/€) | D37: 0 | E37: =E33/E25 -> 76.496647 | F37: =F33/F25 -> 183.60013 | G37: =G33/G25 -> 101.04381
B38: LCOE
C39: LCOE [€/MWh] | D39: ='Project finance'!J24 -> 44.309894 | E39: ='Project finance'!K24 -> 43.664321 | F39: ='Project finance'!L24 -> 43.231391 | G39: ='Project finance'!M24 -> 42.823161
C40: ΔLCOE [€/MWh] | D40: =D39-$D$39 -> 0 | E40: =E39-$D$39 -> -0.64557323 | F40: =F39-$D$39 -> -1.0785029 | G40: =G39-$D$39 -> -1.4867331
C41: ΔLCOE [%] | D41: =D40/D39 -> 0 | E41: =E40/E39 -> -0.014784914 | F41: =F40/F39 -> -0.024947218 | G41: =G40/G39 -> -0.034717968
C43: P50 | D43: P90 | E43: P50 std.dev | F43: Project NPV | G43: Δ NPV
...

Sheet LiDAR
A1: Cost | B1: Vertical profiling LiDAR
A3: A. | B3: Commission fee (setup, onsite delivery, commission) | K3: 0.05
A4: B. | B4: Monthly Rental fee
A5: 1 | B5: WindCube LIDAR Vertical Wind Profiler | C5: $/month | D5: 5000 | E5: [Source] | F5: €/year | G5: =D5*0.9*12 -> 54000 | H5: plus mobilisation/power etc maybe | J5: €/year | K5: =G5 -> 54000 | S5: UK inflation rate
A6: 2 | B6: ZX300 LiDAR | C6: $/month | D6: 4200 | E6: [Source] | F6: €/year | G6: =D6*0.9*12 -> 45360 | J6: €/year | K6: =G6 -> 45360 | S6: Year | T6: Annual Inflation Rate (approx.)
A7: 3 | B7: ZephIR 300 | C7: £/year | D7: 30000 | E7: [Source] | F7: €/year | G7: =30000/0.8 -> 37500 | H7: (* inflation) | J7: €/year | K7: =G7*(1.03^10) -> 50396.864 | P7: =AVERAGE(G5:G7)*15% -> 6843 | S7: 2015 | T7: 0.004
S8: 2016 | T8: 0.01
A9: C. | B9: Power supply / infrastructure cost (For remote deployments, autonomous power supply (solar + battery + fuel cell, diesel generator) is required. The “Power Supply Operation Fee” covers fuel, maintenance etc.) | K9: 0.1 | S9: 2017 | T9: 0.026
A10: D. | B10: Maintenance / servicing / data quality assurance (calibration, repair, data verification (especially for bankable campaigns) | K10: 47000 | S10: 2018 | T10: 0.023
S11: 2019 | T11: 0.017
S12: 2020 | T12: 0.01
B13: Estimate: For upland and big farms => extra power supply/trailer/fuel/security => extra 10-20% | H13: 1 LIDAR | J13: €/year | K13: =AVERAGE(K5:K7)*1.15+K10 -> 104406.8 | M13: 2 drones | N13: =UAVs!J13 -> 135350 | S13: 2021 | T13: 0.025
H14: 2 LIDAR | J14: €/year | K14: =AVERAGE(K5:K7)*1.1+K13 -> 159317.65 | M14: 3 drones | N14: =UAVs!O13 -> 156050 | S14: 2022 | T14: 0.091
S15: 2023 | T15: 0.073
S16: 2024 | T16: 0.022
T17: =AVERAGE(T7:T16) -> 0.0301

Sheet UAVs
A2: Drone cost | B2: (purchase) | C2: $/drone | D2: 13000 | E2: [Source] | F2: €/drone | G2: =D2*0.9 -> 11700 | I2: €/2 drones | J2: =G2*2 -> 23400 | N2: €/3 drones | O2: =G2*3 -> 35100
B3: (purchase) | C3: $/drone | D3: 10000 | E3: [Source] | F3: €/drone | G3: =D3*0.9 -> 9000 | I3: €/2 drones | J3: =G3*2 -> 18000 | N3: €/3 drones | O3: =G3*3 -> 27000
B4: (purchase) | C4: $/drone | D4: =AVERAGE(8000,15000) -> 11500 | E4: [Source] | F4: €/drone | G4: =D4*0.9 -> 10350 | I4: €/2 drones | J4: =G4*2 -> 20700 | N4: €/3 drones | O4: =G4*3 -> 31050
A5: Entry-Level VTOL Drones: $8,000 – $15,000 | E5: [Source]
A7: Availablity | B7: IEC: độ sẵn sàng (data availability) cao, thường >80% trong suốt thời gian đo | I7: hour/year | J7: =8760*0.8 -> 7008 | K7: hour/1.5 year | L7: =J7*1.5 -> 10512
J8: =J7/365 -> 19.2
A10: Salary of pilot + data | C10: 1 day = 3 skips => 3 people | F10: €/person/year | G10: =AVERAGE(39500) -> 39500 | H10: [Source] | J10: =G10*3 -> 118500
A11: Other | C11: 0.15 | D11: ~ 6500 (in LiDAR) | J11: 6500
I13: €/year | J13: =SUM(AVERAGE(J2:J4)*50%,J10,J11) -> 135350 | N13: €/3 drones | O13: =SUM(AVERAGE(O2:O4),J10,J11) -> 156050
A19: Renting drone | B19: 60% purchase price
A20: Control system
A21: Power supply/infrastructual
A22: Onsite install/setup + decomission
A23: Pilot | B23: 3 people/day

Sheet Renting LiDAR - UAVs
B2: ONE-YEAR CAMPAIGN of ONSITE WIND MEASUREMENT
B4: SCENARIO 1 : LiDAR_1 | K4: SCENARIO 2 : LiDAR_2
B5: No. | C5: Cost component | D5: Unit 1 | E5: Quota 1 | F5: Unit 2 | G5: Quota 2 | H5: Quantity | I5: Source | K5: No. | L5: Cost component | M5: Unit 1 | N5: Quota 1 | O5: Unit 2 | P5: Quota 2 | Q5: Quantity | R5: Source
B6: 1 | C6: Yearly Rental fee of LiDARs | D6: €/year | E6: =4700*12 -> 56400 | F6: LiDAR | G6: 1 | H6: 56400 | I6: Quote 1 | K6: 1 | L6: Monthly Rental fee | M6: €/year | N6: =4700*12 -> 56400 | O6: LiDAR | P6: 2 | Q6: =N6*P6 -> 112800 | R6: Quote 1
B7: 2 | C7: Commission fee & delivery (setup, onsite delivery, commission, control system) | D7: €/km | E7: 1.5 | F7: km | G7: =1000*2 -> 2000 | H7: 3000 | I7: Assumed | K7: 2 | L7: Commission fee & delivery | M7: €/km | N7: 1.5 | O7: km | P7: =1000*2 -> 2000 | Q7: =N7*P7 -> 3000 | R7: Assumed
B8: 3 | C8: Control system & Maintainance (transport trailer, installation and operation of LiDAR measuring system, Mobile GSM connection, Mounting bracket for PV Panels) | D8: €/year | E8: =1155*12 -> 13860 | F8: LiDAR | G8: 1 | H8: 13860 | I8: Quote 2 | K8: 3 | L8: Control system & Maintainance (transport trailer, installation and operation of LiDAR measuring system, Mobile GSM connection, Mounting bracket for PV Panels) | M8: €/year | N8: =1155*12 -> 13860 | O8: LiDAR | P8: 2 | Q8: =N8*P8 -> 27720 | R8: Quote 2
B9: 4 | C9: Power supply | D9: €/kWh | E9: 0.25 | F9: kWh/system | G9: =150*8760/1000 -> 1314 | H9: 329.5 | I9: Assumed | K9: 4 | L9: Power supply / infrastructure cost | M9: €/kWh | N9: 0.25 | O9: kWh/2system | P9: =150*8760/1000*2 -> 2628 | Q9: =N9*P9+3 -> 660 | R9: Assumed
B10: 5 | C10: Data handle | D10: €/dataset | E10: 2000 | F10: dataset | G10: 1 | H10: 2000 | I10: Quote 3 | K10: 5 | L10: Data handle | M10: €/dataset | N10: 2000 | O10: dataset | P10: 2 | Q10: =N10*P10 -> 4000 | R10: Quote 3
B11: TOTAL | D11: € | H11: 75589.5 | K11: TOTAL | M11: € | Q11: =SUM(Q7:Q8,Q6,Q9:Q10) -> 148180
B13: SCENARIO 3 : UAV_2 | K13: SCENARIO 4 : UAV_4
B14: No. | C14: Cost component | D14: Unit 1 | E14: Quota 1 | F14: Unit 2 | G14: Quota 2 | H14: Quantity | I14: NOTE | K14: No. | L14: Cost component | M14: Unit 1 | N14: Quota 1 | O14: Unit 2 | P14: Quota 2 | Q14: Quantity | R14: NOTE
B15: 1 | C15: Yearly rental fee of drones and control system | D15: €/year | H15: 121503 | K15: 1 | L15: Yearly rental fee of drones and control system | M15: €/year | Q15: 198003
C16: Profit margin | D16: €/year | E16: (confidential) | F16: year | G16: 1 | H16: (confidential) | I16: Alveo AB | L16: Profit margin | M16: €/year | N16: (confidential) | O16: year | P16: 1 | Q16: (confidential) | R16: Alveo AB
C17: CAPEX_Drone purchase price | D17: €/drone | E17: =AVERAGE(10000,25000) -> 17500 | F17: drone | G17: 2 | H17: 35000 | I17: Quote 4 | L17: CAPEX_Drone purchase price | M17: €/drone | N17: =AVERAGE(10000,25000) -> 17500 | O17: drone | P17: 4 | Q17: 70000 | R17: Quote 4
C18: CAPEX_Communication system | D18: €/system | E18: =AVERAGE(1100,1200) -> 1150 | F18: system | G18: 1 | H18: 1150 | I18: Quote 5 | L18: CAPEX_Communication system | M18: €/system | N18: =AVERAGE(1100,1200) -> 1150 | O18: system | P18: 1 | Q18: 1150 | R18: Quote 5
C19: CAPEX_Battery & Charger | D19: €/battery | E19: =AVERAGE(1350,1550) -> 1450 | F19: battery | G19: 1 | H19: 1450 | I19: Quote 6 | L19: CAPEX_Battery & Charger | M19: €/battery | N19: =AVERAGE(1350,1550) -> 1450 | O19: battery | P19: 1 | Q19: 1450 | R19: Quote 6
C20: CAPEX_Disel generator | D20: €/marchine | E20: 4500 | F20: marchine | G20: 1 | H20: 4500 | I20: Quote 7 | L20: CAPEX_Disel generator | M20: €/marchine | N20: 4500 | O20: marchine | P20: 1 | Q20: 4500 | R20: Quote 7
C21: CAPEX_12 solar panels | D21: €/panel | E21: 140 | F21: panel | G21: 12 | H21: 1680 | I21: Quote 8 | L21: CAPEX_12 solar panels | M21: €/panel | N21: 140 | O21: panel | P21: 12 | Q21: 1680 | R21: Quote 8
C22: CAPEX_Short masts | D22: €/system | E22: =AVERAGE(400,900) -> 650 | F22: mast | G22: 1 | H22: 650 | I22: Quote 9 | L22: CAPEX_Short masts | M22: €/system | N22: =AVERAGE(400,900) -> 650 | O22: mast | P22: 1 | Q22: 650 | R22: Quote 9
C23: CAPEX_Container & others | D23: €/system | E23: =AVERAGE(390,650)*1.1 -> 572 | F23: system | G23: 1 | H23: 572 | I23: Quote 10 | L23: CAPEX_Container & others | M23: €/system | N23: =AVERAGE(390,650)*1.1 -> 572 | O23: system | P23: 1 | Q23: 572 | R23: Quote 10
C24: OPEX_Operational specialist salary | D24: €/person/year | E24: (confidential) | F24: %FTE | G24: (confidential) | H24: (confidential) | I24: Alveo AB | L24: OPEX_Operational specialist salary | M24: €/person/year | N24: (confidential) | O24: %FTE | P24: (confidential) | Q24: (confidential) | R24: Alveo AB
C25: OPEX_Drone maintainance | D25: €/drone/year | E25: =AVERAGE(4000,12000) -> 8000 | F25: drone | G25: 2 | H25: 16000 | I25: Quote 11 | L25: OPEX_Drone maintainance | M25: €/drone/year | N25: =AVERAGE(4000,12000) -> 8000 | O25: drone | P25: 4 | Q25: 32000 | R25: Quote 11
B26: 2 | C26: Commission fee & delivery | D26: €/km | E26: 1.5 | F26: km | G26: =1000*2 -> 2000 | H26: 3000 | I26: Assumed | K26: 2 | L26: Commission fee & delivery (setup, onsite delivery, commission, control system) | M26: €/km | N26: 1.5 | O26: km | P26: =1000*2 -> 2000 | Q26: 3000 | R26: Assumed
B27: 4 | C27: Power supply | D27: €/kWh | E27: (confidential) | F27: kWh/system | G27: (confidential) | H27: (confidential) | I27: Alveo AB | K27: 4 | L27: Power supply | M27: €/kWh | N27: 0.25 | O27: kWh/system | P27: =150*8760/1000 -> 1314 | Q27: 329.5 | R27: Alveo AB
B28: 5 | C28: Data handle | D28: €/dataset | E28: 2000 | F28: dataset | G28: 1 | H28: 2000 | K28: 5 | L28: Data handle | M28: €/dataset | N28: 2000 | O28: dataset | P28: 2 | Q28: 4000 | R28: Quote 3
B29: TOTAL | H29: 126832.5 | K29: TOTAL | Q29: 205332.5
B32: References of Quotes:
B33: Quote 1 | C33: ProfEC Ventus GmbH. (2025c, October). WindCube LIDAR Mietservice (monthly). https://shop.profec-ventus.com/product_info.php?info=p423_windcube-lidar-rental-service--monthly-.html
B34: Quote 2 | C34: ProfEC Ventus GmbH. (2025b, October). LiDAR Trailer Rental Service. One Stop Wind Shop: Measurement Equipment and Services. http://shop.profec-ventus.com/index.php
B35: Quote 3 | C35: ProfEC Ventus GmbH. (2025a, October). Bankable Installation Report—Ilac-MRA accred-ited as per ISO 17025. One Stop Wind Shop: Measurement Equipment and Ser-vices. https://shop.profec-ventus.com/product_info.php?info=p455_bankable-installation-report---ilac-mra-accredited-as-per-iso-17025.html
B36: Quote 4 | C36: Hinaray. (2025, June 3). How Much Does a VTOL Fixed Wing Drone Cost in 2025. https://hinaray.com/how-much-does-a-vtol-fixed-wing-drone-cost-in-2025/
B37: Quote 5 | C37: Alibaba.com. (2025f). Networking Air-ground communication system. https://www.alibaba.com/
B38: Quote 6 | C38: Alibaba.com. (2025a). 10kwh 15KWH 20KWH Stackable Battery Home Energy Storage System. https://www.alibaba.com/
B39: Quote 7 | C39: Alibaba.com. (2025c). Diesel Generator Diesel Silent. Www.Alibaba.Com. https://www.alibaba.com/
B40: Quote 8 | C40: Alibaba.com. (2025d). Home Solar Price 500w PV Panels. https://www.alibaba.com/
B41: Quote 9 | C41: Alibaba.com. (2025e). Lightweight Portable Telescopic Mast By Air. https://www.alibaba.com/
B42: Quote 10 | C42: Alibaba.com. (2025b). Detachable Container. https://www.alibaba.com/
B43: Quote 11 | C43: FinModelsLab.com. (2025). Drone Maintenance Cost Breakdown: Save on Operating Ex-penses. https://finmodelslab.com/blogs/operating-costs/drone-maintenance

Sheet Project finance
C1: Installed capacity | E1: 120 | F1: MW
B2: ONSHORE PROJECT COST | H2: CALCULATION
B3: Lifetime | C3: year | D3: 25 | H3: No | I3: Uncertainty components | J3: ='COMPARISON RESULTs'!D4 -> LiDAR_1 | K3: ='COMPARISON RESULTs'!E4 -> LiDAR_2 | L3: ='COMPARISON RESULTs'!F4 -> UAV_2 | M3: ='COMPARISON RESULTs'!G4 -> UAV_4
B4: CAPEX | C4: E/MW | D4: =AVERAGE(1300000,1900000) -> 1600000 | E4: =D4*E1 -> 192000000 | F4: Source: Fraunhofer ISE | H4: ENERGY YIELD
B5: Development phase (pre-construction) | C5: E/MW | D5: =D4*10% -> 160000 | F5: Assume: 10% CAPEX | I5: Mean AEP (P50) (MWh) | J5: ='COMPARISON RESULTs'!D12 -> 468892.97 | K5: ='COMPARISON RESULTs'!E12 -> 470760.89 | L5: ='COMPARISON RESULTs'!F12 -> 471390.14 | M5: ='COMPARISON RESULTs'!G12 -> 472423.11
B6: Construction phase | C6: E/MW | D6: =D4-D5 -> 1440000 | F6: Assume: 90% CAPEX | I6: P90 (MWh) | J6: ='COMPARISON RESULTs'!D17 -> 457106.36 | K6: ='COMPARISON RESULTs'!E17 -> 463535.8 | L6: ='COMPARISON RESULTs'!F17 -> 468140.86 | M6: ='COMPARISON RESULTs'!G17 -> 472303.49
B7: OPEX | C7: E/MW/year | E7: =E8+E9 -> 7122250.8 | I7: P90/P50 ratio (%) | J7: =J6/J5 -> 0.9748629 | K7: =K6/K5 -> 0.9846523 | L7: =L6/L5 -> 0.99310702 | M7: =M6/M5 -> 0.9997468
B8: Fixed cost | C8: E/MW/year | D8: =32*1000 -> 32000 | E8: =D8*E1 -> 3840000 | F8: Source: Fraunhofer ISE | I8: StdDev of P50 (MWh) | J8: ='COMPARISON RESULTs'!D15 -> 8916.1348 | K8: ='COMPARISON RESULTs'!E15 -> 5515.1486 | L8: ='COMPARISON RESULTs'!F15 -> 2385.3672 | M8: ='COMPARISON RESULTs'!G15 -> 92.086515
B9: Variable cost | C9: E/MWh | D9: =0.007*1000 -> 7 | E9: =D9*'COMPARISON RESULTs'!D12 -> 3282250.8 | F9: Source: Fraunhofer ISE | I9: StdDev of P50 (%) | J9: ='COMPARISON RESULTs'!D16 -> 0.019015288 | K9: ='COMPARISON RESULTs'!E16 -> 0.011715392 | L9: ='COMPARISON RESULTs'!F16 -> 0.0050602822 | M9: ='COMPARISON RESULTs'!G16 -> 0.00019492382
H10: COST OF CAMPAIGN
B11: TARIFF | I11: Cost (€) | J11: ='Renting LiDAR - UAVs'!H11 -> 75589.5 | K11: ='Renting LiDAR - UAVs'!Q11 -> 148180 | L11: ='Renting LiDAR - UAVs'!H29 -> 126832.5 | M11: ='Renting LiDAR - UAVs'!Q29 -> 205332.5
B12: Bid price of onshore project | C12: E/MWh | D12: =AVERAGE(57.3,73.5) -> 65.4 | F12: Source: 5.73 and 7.35 ct/kWh | I12: Δ Cost (€) | J12: =J11-$J$11 -> 0 | K12: =K11-$J$11 -> 72590.5 | L12: =L11-$J$11 -> 51243 | M12: =M11-$J$11 -> 129743
F13: Align with data of Fraunhofer ISE | H13: FINANCIAL CASH FLOW
I14: DSCR target | J14: =D24 -> 1.35 | K14: =J14 -> 1.35 | L14: =J14 -> 1.35 | M14: =J14 -> 1.35
B15: PROJECT FINANCE STRUSTURE (TARGET) | I15: Revenue_P90 (€/year) | J15: =$D$12*J6 -> 29894756 | K15: =$D$12*K6 -> 30315241 | L15: =$D$12*L6 -> 30616412 | M15: =$D$12*M6 -> 30888648
B16: Share of debt (15 years) | C16: % | D16: 0.8 | F16: Source: Fraunhofer ISE | I16: OPEX (€/year) | J16: =-($E$8+$D$9*J6) -> -7039744.5 | K16: =-($E$8+$D$9*K6) -> -7084750.6 | L16: =-($E$8+$D$9*L6) -> -7116986 | M16: =-($E$8+$D$9*M6) -> -7146124.4
B17: Share of equity (15 years) | C17: % | D17: =1-D16 -> 0.2 | F17: Source: Fraunhofer ISE | I17: Debt service_DSCR target (year) | J17: =-(J15+J16)/J14 -> -16929638 | K17: =-(K15+K16)/K14 -> -17207771 | L17: =-(L15+L16)/L14 -> -17406982 | M17: =-(M15+M16)/M14 -> -17587055
B18: Cost of debt | C18: % | D18: 0.055 | F18: Source: Fraunhofer ISE | I18: Debt capacity (€/project) | J18: =-J17*(1-(1+$D$18)^(-15))/$D$18 -> 1.6993261e+08 | K18: =-K17*(1-(1+$D$18)^(-15))/$D$18 -> 1.7272439e+08 | L18: =-L17*(1-(1+$D$18)^(-15))/$D$18 -> 1.74724e+08 | M18: =-M17*(1-(1+$D$18)^(-15))/$D$18 -> 1.7653148e+08
B19: Cost of equity (Return on equity) | C19: % | D19: 0.07 | F19: Source: Fraunhofer ISE | I19: Equity size (€/project) | J19: =E4-J18 -> 22067389 | K19: =$E$4-K12-K18 -> 19203017 | L19: =$E$4-L12-L18 -> 17224762 | M19: =$E$4-M12-M18 -> 15338772
I20: Share of debt (%) | J20: =J18/$E$4 -> 0.88506568 | K20: =K18/$E$4 -> 0.89960621 | L20: =L18/$E$4 -> 0.91002081 | M20: =M18/$E$4 -> 0.91943482
I21: Share of debt (%) | J21: =1-J20 -> 0.11493432 | K21: =1-K20 -> 0.10039379 | L21: =1-L20 -> 0.089979191 | M21: =1-M20 -> 0.080565183
I22: WACC (%) | J22: =(J19/$E$4*$D$19)+(J18/$E$4*$D$18*(1-$D$25)) -> 0.046988292 | K22: =(K19/$E$4*$D$19)+(K18/$E$4*$D$18*(1-$D$25)) -> 0.046583773 | L22: =(L19/$E$4*$D$19)+(L18/$E$4*$D$18*(1-$D$25)) -> 0.046320777 | M22: =(M19/$E$4*$D$19)+(M18/$E$4*$D$18*(1-$D$25)) -> 0.046047393
B23: WACC (normial) | C23: % | D23: 0.058 | F23: Source: Fraunhofer ISE | I23: NPV (€/project) | J23: ='Yearly cashflow'!C11 -> 73655594 | K23: ='Yearly cashflow'!C24 -> 79208524 | L23: ='Yearly cashflow'!C37 -> 83063816 | M23: ='Yearly cashflow'!C50 -> 86765322
B24: DSCR target | D24: 1.35 | F24: Assume | I24: LCOE (€/MWh) | J24: ='Yearly cashflow'!C13 -> 44.309894 | K24: ='Yearly cashflow'!C26 -> 43.664321 | L24: ='Yearly cashflow'!C39 -> 43.231391 | M24: ='Yearly cashflow'!C52 -> 42.823161
B25: Tax | D25: 0.2 | F25: Assume
B28: Note:
A29: (*) | B29: DSCR (Debt Service Coverage Ratio) is a constraint to ensure that the bank can recover debt from project cash flow.
B30: To be bankable, DSCR of a project needs to be at least 1 (DSCR ≥ 1). In Germany the DSCR target is ~1.2 for typical simple onshore wind farms
B31: As the uncertainty of AEP (StdDev %) decreases, P90/P50 ratio increases → Banks reduce target DSCR requirement (from 1.35 → 1.30 → 1.25,…).
B32: Assumption:
B33: DSCR target | C33: 1.2 | D33: For stable, low-risk assets, typical onshore wind farm in flat terrain
B34: DSCR target | C34: 1.35 | D34: For typical offshore or higher-uncertainty onshore projects
B35: DSCR target | C35: 1.5 | D35: For very risky projects

Sheet Yearly cashflow
B3: Year | C3: 0 | D3: 1 | E3: 2 | F3: 3 | G3: 4 | H3: 5 | I3: 6 | J3: 7 | K3: 8 | L3: 9 | M3: 10 | N3: 11 | O3: 12 | P3: 13 | Q3: 14 | R3: 15 | S3: 16 | T3: 17 | U3: 18 | V3: 19 | W3: 20 | X3: 21 | Y3: 22 | Z3: 23 | AA3: 24 | AB3: 25
B4: Scenario 1
B5: CAPEX | C5: =-'Project finance'!E4 -> -192000000
B6: OPEX | D6: ='Project finance'!J16 -> -7039744.5 | E6: =D6 -> -7039744.5 | F6: =E6 -> -7039744.5 | G6: =F6 -> -7039744.5 | H6: =G6 -> -7039744.5 | I6: =H6 -> -7039744.5 | J6: =I6 -> -7039744.5 | K6: =J6 -> -7039744.5 | L6: =K6 -> -7039744.5 | ... AB6: =AA6 -> -7039744.5
B7: Revenue | D7: ='Project finance'!J15 -> 29894756 | E7: =D7 -> 29894756 | F7: =E7 -> 29894756 | G7: =F7 -> 29894756 | H7: =G7 -> 29894756 | I7: =H7 -> 29894756 | J7: =I7 -> 29894756 | K7: =J7 -> 29894756 | L7: =K7 -> 29894756 | ... AB7: =AA7 -> 29894756
B8: EBIT | D8: =SUM(D6)+D7 -> 22855011 | E8: =SUM(E6)+E7 -> 22855011 | F8: =SUM(F6)+F7 -> 22855011 | G8: =SUM(G6)+G7 -> 22855011 | H8: =SUM(H6)+H7 -> 22855011 | I8: =SUM(I6)+I7 -> 22855011 | J8: =SUM(J6)+J7 -> 22855011 | K8: =SUM(K6)+K7 -> 22855011 | ... AB8: =SUM(AB6)+AB7 -> 22855011
B9: WACC | C9: ='Project finance'!J22 -> 0.046988292
B10: PV_yearly | C10: =(C8*(1-20%)+C5)/((1+$C$9)^C3) -> -192000000 | D10: =(D8*(1-20%)+D5)/((1+$C$9)^D3) -> 17463432 | E10: =(E8*(1-20%)+E5)/((1+$C$9)^E3) -> 16679682 | F10: =(F8*(1-20%)+F5)/((1+$C$9)^F3) -> 15931107 | G10: =(G8*(1-20%)+G5)/((1+$C$9)^G3) -> 15216127 | H10: =(H8*(1-20%)+H5)/((1+$C$9)^H3) -> 14533235 | I10: =(I8*(1-20%)+I5)/((1+$C$9)^I3) -> 13880991 | J10: =(J8*(1-20%)+J5)/((1+$C$9)^J3) -> 13258019 | ... AB10: =(AB8*(1-20%)+AB5)/((1+$C$9)^AB3) -> 5801306.3
B11: NPV | C11: =SUM(C10:AB10) -> 73655594
B13: LCOE | C13: =-SUM(C14:AB14)/SUM(C15:AB15) -> 44.309894
B14: Discounted CAPEX and OPEX | C14: =SUM(C5:C6)/((1+$C$9)^'Yearly cashflow'!C3) -> -192000000 | D14: =SUM(D5:D6)/((1+$C$9)^'Yearly cashflow'!D3) -> -6723804.4 | E14: =SUM(E5:E6)/((1+$C$9)^'Yearly cashflow'!E3) -> -6422043.5 | F14: =SUM(F5:F6)/((1+$C$9)^'Yearly cashflow'!F3) -> -6133825.6 | G14: =SUM(G5:G6)/((1+$C$9)^'Yearly cashflow'!G3) -> -5858542.6 | H14: =SUM(H5:H6)/((1+$C$9)^'Yearly cashflow'!H3) -> -5595614.3 | I14: =SUM(I5:I6)/((1+$C$9)^'Yearly cashflow'!I3) -> -5344486 | J14: =SUM(J5:J6)/((1+$C$9)^'Yearly cashflow'!J3) -> -5104628.3 | ... AB14: =SUM(AB5:AB6)/((1+$C$9)^'Yearly cashflow'!AB3) -> -2233630.2
B15: Discounted E.Production | C15: 0 | D15: ='Project finance'!$J$6/((1+$C$9)^D3) -> 436591.66 | E15: ='Project finance'!$J$6/((1+$C$9)^E3) -> 416997.65 | F15: ='Project finance'!$J$6/((1+$C$9)^F3) -> 398283.01 | G15: ='Project finance'!$J$6/((1+$C$9)^G3) -> 380408.28 | H15: ='Project finance'!$J$6/((1+$C$9)^H3) -> 363335.75 | I15: ='Project finance'!$J$6/((1+$C$9)^I3) -> 347029.43 | J15: ='Project finance'!$J$6/((1+$C$9)^J3) -> 331454.93 | K15: ='Project finance'!$J$6/((1+$C$9)^K3) -> 316579.4 | ... AB15: ='Project finance'!$J$6/((1+$C$9)^AB3) -> 145034.6
B17: Scenario 2
B18: CAPEX | C18: =-'Project finance'!E4+'Project finance'!K12 -> -1.9192741e+08
B19: OPEX | D19: ='Project finance'!K16 -> -7084750.6 | E19: =D19 -> -7084750.6 | F19: =E19 -> -7084750.6 | G19: =F19 -> -7084750.6 | H19: =G19 -> -7084750.6 | I19: =H19 -> -7084750.6 | J19: =I19 -> -7084750.6 | K19: =J19 -> -7084750.6 | L19: =K19 -> -7084750.6 | ... AB19: =AA19 -> -7084750.6
B20: Revenue | D20: ='Project finance'!K15 -> 30315241 | E20: =D20 -> 30315241 | F20: =E20 -> 30315241 | G20: =F20 -> 30315241 | H20: =G20 -> 30315241 | I20: =H20 -> 30315241 | J20: =I20 -> 30315241 | K20: =J20 -> 30315241 | L20: =K20 -> 30315241 | ... AB20: =AA20 -> 30315241
B21: EBIT | D21: =SUM(D18:D19)+D20 -> 23230491 | E21: =SUM(E18:E19)+E20 -> 23230491 | F21: =SUM(F18:F19)+F20 -> 23230491 | G21: =SUM(G18:G19)+G20 -> 23230491 | H21: =SUM(H18:H19)+H20 -> 23230491 | I21: =SUM(I18:I19)+I20 -> 23230491 | J21: =SUM(J18:J19)+J20 -> 23230491 | K21: =SUM(K18:K19)+K20 -> 23230491 | ... AB21: =SUM(AB18:AB19)+AB20 -> 23230491
B22: WACC | C22: ='Project finance'!K22 -> 0.046583773
B23: PV_yearly | C23: =(C21*(1-20%)+C18)/((1+$C$22)^C3) -> -1.9192741e+08 | D23: =(D21*(1-20%)+D18)/((1+$C$22)^D3) -> 17757195 | E23: =(E21*(1-20%)+E18)/((1+$C$22)^E3) -> 16966817 | F23: =(F21*(1-20%)+F18)/((1+$C$22)^F3) -> 16211619 | G23: =(G21*(1-20%)+G18)/((1+$C$22)^G3) -> 15490034 | H23: =(H21*(1-20%)+H18)/((1+$C$22)^H3) -> 14800568 | I23: =(I21*(1-20%)+I18)/((1+$C$22)^I3) -> 14141790 | J23: =(J21*(1-20%)+J18)/((1+$C$22)^J3) -> 13512335 | ... AB23: =(AB21*(1-20%)+AB18)/((1+$C$22)^AB3) -> 5953857.6
B24: NPV | C24: =SUM(C23:AB23) -> 79208524
B26: LCOE | C26: =-SUM(C27:AB27)/SUM(C28:AB28) -> 43.664321
B27: Discounted CAPEX and OPEX | C27: =SUM(C18:C19)/((1+$C$22)^C3) -> -1.9192741e+08 | D27: =SUM(D18:D19)/((1+$C$22)^D3) -> -6769406.1 | E27: =SUM(E18:E19)/((1+$C$22)^E3) -> -6468097.7 | F27: =SUM(F18:F19)/((1+$C$22)^F3) -> -6180200.6 | G27: =SUM(G18:G19)/((1+$C$22)^G3) -> -5905118 | H27: =SUM(H18:H19)/((1+$C$22)^H3) -> -5642279.3 | I27: =SUM(I18:I19)/((1+$C$22)^I3) -> -5391139.7 | J27: =SUM(J18:J19)/((1+$C$22)^J3) -> -5151178.4 | ... AB27: =SUM(AB18:AB19)/((1+$C$22)^AB3) -> -2269732.3
B28: Discounted E.Production | C28: 0 | D28: ='Project finance'!$K$6/((1+$C$22)^D3) -> 442903.67 | E28: ='Project finance'!$K$6/((1+$C$22)^E3) -> 423189.89 | F28: ='Project finance'!$K$6/((1+$C$22)^F3) -> 404353.58 | G28: ='Project finance'!$K$6/((1+$C$22)^G3) -> 386355.67 | H28: ='Project finance'!$K$6/((1+$C$22)^H3) -> 369158.86 | I28: ='Project finance'!$K$6/((1+$C$22)^I3) -> 352727.48 | J28: ='Project finance'!$K$6/((1+$C$22)^J3) -> 337027.47 | K28: ='Project finance'!$K$6/((1+$C$22)^K3) -> 322026.27 | ... AB28: ='Project finance'!$K$6/((1+$C$22)^AB3) -> 148502.36
B30: Scenario 3
B31: CAPEX | C31: =-'Project finance'!E4+'Project finance'!L12 -> -191948757
B32: OPEX | D32: ='Project finance'!L16 -> -7116986 | E32: =D32 -> -7116986 | F32: =E32 -> -7116986 | G32: =F32 -> -7116986 | H32: =G32 -> -7116986 | I32: =H32 -> -7116986 | J32: =I32 -> -7116986 | K32: =J32 -> -7116986 | L32: =K32 -> -7116986 | ... AB32: =AA32 -> -7116986
B33: Revenue | D33: ='Project finance'!L15 -> 30616412 | E33: =D33 -> 30616412 | F33: =E33 -> 30616412 | G33: =F33 -> 30616412 | H33: =G33 -> 30616412 | I33: =H33 -> 30616412 | J33: =I33 -> 30616412 | K33: =J33 -> 30616412 | L33: =K33 -> 30616412 | ... AB33: =AA33 -> 30616412
B34: EBIT | D34: =SUM(D31:D32)+D33 -> 23499426 | E34: =SUM(E31:E32)+E33 -> 23499426 | F34: =SUM(F31:F32)+F33 -> 23499426 | G34: =SUM(G31:G32)+G33 -> 23499426 | H34: =SUM(H31:H32)+H33 -> 23499426 | I34: =SUM(I31:I32)+I33 -> 23499426 | J34: =SUM(J31:J32)+J33 -> 23499426 | K34: =SUM(K31:K32)+K33 -> 23499426 | ... AB34: =SUM(AB31:AB32)+AB33 -> 23499426
B35: WACC | C35: ='Project finance'!L22 -> 0.046320777
B36: PV_yearly | C36: =(C34*(1-20%)+C31)/((1+$C$35)^C3) -> -191948757 | D36: =(D34*(1-20%)+D31)/((1+$C$35)^D3) -> 17967283 | E36: =(E34*(1-20%)+E31)/((1+$C$35)^E3) -> 17171868 | F36: =(F34*(1-20%)+F31)/((1+$C$35)^F3) -> 16411667 | G36: =(G34*(1-20%)+G31)/((1+$C$35)^G3) -> 15685120 | H36: =(H34*(1-20%)+H31)/((1+$C$35)^H3) -> 14990738 | I36: =(I34*(1-20%)+I31)/((1+$C$35)^I3) -> 14327095 | J36: =(J34*(1-20%)+J31)/((1+$C$35)^J3) -> 13692833 | ... AB36: =(AB34*(1-20%)+AB31)/((1+$C$35)^AB3) -> 6060745.1
B37: NPV | C37: =SUM(C36:AB36) -> 83063816
B39: LCOE | C39: =-SUM(C40:AB40)/SUM(C41:AB41) -> 43.231391
B40: Discounted CAPEX and OPEX | C40: =SUM(C31:C32)/((1+$C$35)^C3) -> -191948757 | D40: =SUM(D31:D32)/((1+$C$35)^D3) -> -6801916 | E40: =SUM(E31:E32)/((1+$C$35)^E3) -> -6500794.2 | F40: =SUM(F31:F32)/((1+$C$35)^F3) -> -6213003 | G40: =SUM(G31:G32)/((1+$C$35)^G3) -> -5937952.5 | H40: =SUM(H31:H32)/((1+$C$35)^H3) -> -5675078.4 | I40: =SUM(I31:I32)/((1+$C$35)^I3) -> -5423841.9 | J40: =SUM(J31:J32)/((1+$C$35)^J3) -> -5183727.6 | ... AB40: =SUM(AB31:AB32)/((1+$C$35)^AB3) -> -2294430.4
B41: Discounted E.Production | C41: 0 | D41: ='Project finance'!$L$6/((1+$C$35)^D3) -> 447416.2 | E41: ='Project finance'!$L$6/((1+$C$35)^E3) -> 427609.01 | F41: ='Project finance'!$L$6/((1+$C$35)^F3) -> 408678.7 | G41: ='Project finance'!$L$6/((1+$C$35)^G3) -> 390586.43 | H41: ='Project finance'!$L$6/((1+$C$35)^H3) -> 373295.11 | I41: ='Project finance'!$L$6/((1+$C$35)^I3) -> 356769.28 | J41: ='Project finance'!$L$6/((1+$C$35)^J3) -> 340975.05 | K41: ='Project finance'!$L$6/((1+$C$35)^K3) -> 325880.04 | ... AB41: ='Project finance'!$L$6/((1+$C$35)^AB3) -> 150922.96
B43: Scenario 4
B44: CAPEX | C44: =-'Project finance'!E4+'Project finance'!M12 -> -191870257
B45: OPEX | D45: ='Project finance'!M16 -> -7146124.4 | E45: =D45 -> -7146124.4 | F45: =E45 -> -7146124.4 | G45: =F45 -> -7146124.4 | H45: =G45 -> -7146124.4 | I45: =H45 -> -7146124.4 | J45: =I45 -> -7146124.4 | K45: =J45 -> -7146124.4 | L45: =K45 -> -7146124.4 | ... AB45: =AA45 -> -7146124.4
B46: Revenue | D46: ='Project finance'!M15 -> 30888648 | E46: =D46 -> 30888648 | F46: =E46 -> 30888648 | G46: =F46 -> 30888648 | H46: =G46 -> 30888648 | I46: =H46 -> 30888648 | J46: =I46 -> 30888648 | K46: =J46 -> 30888648 | L46: =K46 -> 30888648 | ... AB46: =AA46 -> 30888648
B47: EBIT | D47: =SUM(D44:D45)+D46 -> 23742524 | E47: =SUM(E44:E45)+E46 -> 23742524 | F47: =SUM(F44:F45)+F46 -> 23742524 | G47: =SUM(G44:G45)+G46 -> 23742524 | H47: =SUM(H44:H45)+H46 -> 23742524 | I47: =SUM(I44:I45)+I46 -> 23742524 | J47: =SUM(J44:J45)+J46 -> 23742524 | K47: =SUM(K44:K45)+K46 -> 23742524 | ... AB47: =SUM(AB44:AB45)+AB46 -> 23742524
B48: WACC | C48: ='Project finance'!M22 -> 0.046047393
...

Sheet Sheet1
B1: 1 | C1: 2 | D1: 3 | E1: 4
B2: 466.82612 | C2: 462.665 | D2: 470.20708 | E2: 469.65964
B3: 460.78801 | C3: 474.88329 | D3: 470.253 | E3: 469.71517
B4: 484.88182 | C4: 451.61756 | D4: 470.28427 | E4: 469.62378
B5: 470.03249 | C5: 470.24617 | D5: 470.04713 | E5: 469.57763
B6: 470.43056 | C6: 467.47799 | D6: 470.1446 | E6: 469.61203
B7: 481.5593 | C7: 470.09262 | D7: 470.22225 | E7: 469.67131
B8: 452.02148 | C8: 474.60376 | D8: 470.14075 | E8: 469.62716
B9: 470.54974 | C9: 458.55589 | D9: 470.14672 | E9: 469.64888
B10: 465.98177 | C10: 469.61035 | D10: 470.21259 | E10: 469.62984
B11: 455.34208 | C11: 468.31371 | D11: 470.14362 | E11: 469.66503
B12: 460.87234 | C12: 473.09258 | D12: 470.18051 | E12: 469.57974
... B1001: 470.04025 | C1001: 463.13864 | D1001: 470.17586 | E1001: 469.63126
